[2025-01-27T19:00:52.797-0300] {taskinstance.py:1956} INFO - Dependencies all met for dep_context=non-requeueable deps ti=<TaskInstance: load_data.wait_step_1 manual__2025-01-27T21:51:20+00:00 [None]>
[2025-01-27T19:00:52.800-0300] {taskinstance.py:1956} INFO - Dependencies all met for dep_context=requeueable deps ti=<TaskInstance: load_data.wait_step_1 manual__2025-01-27T21:51:20+00:00 [None]>
[2025-01-27T19:00:52.801-0300] {taskinstance.py:2170} INFO - Starting attempt 3 of 3
[2025-01-27T19:00:52.897-0300] {taskinstance.py:2191} INFO - Executing <Task(ExternalTaskSensor): wait_step_1> on 2025-01-27 21:51:20+00:00
[2025-01-27T19:00:52.901-0300] {standard_task_runner.py:60} INFO - Started process 182654 to run task
[2025-01-27T19:00:52.903-0300] {standard_task_runner.py:87} INFO - Running: ['airflow', 'tasks', 'run', 'load_data', 'wait_step_1', 'manual__2025-01-27T21:51:20+00:00', '--job-id', '71', '--raw', '--subdir', 'DAGS_FOLDER/step2.py', '--cfg-path', '/tmp/tmpztufxumz']
[2025-01-27T19:00:52.904-0300] {standard_task_runner.py:88} INFO - Job 71: Subtask wait_step_1
[2025-01-27T19:00:52.996-0300] {task_command.py:423} INFO - Running <TaskInstance: load_data.wait_step_1 manual__2025-01-27T21:51:20+00:00 [running]> on host victor-MS-7C52
[2025-01-27T19:00:53.175-0300] {taskinstance.py:2480} INFO - Exporting env vars: AIRFLOW_CTX_DAG_OWNER='airflow' AIRFLOW_CTX_DAG_ID='load_data' AIRFLOW_CTX_TASK_ID='wait_step_1' AIRFLOW_CTX_EXECUTION_DATE='2025-01-27T21:51:20+00:00' AIRFLOW_CTX_TRY_NUMBER='3' AIRFLOW_CTX_DAG_RUN_ID='manual__2025-01-27T21:51:20+00:00'
[2025-01-27T19:00:53.176-0300] {external_task.py:260} INFO - Poking for DAG 'extract_data' on 2025-01-27T21:51:20+00:00 ... 
[2025-01-27T19:01:53.178-0300] {external_task.py:260} INFO - Poking for DAG 'extract_data' on 2025-01-27T21:51:20+00:00 ... 
[2025-01-27T19:02:05.059-0300] {local_task_job_runner.py:302} WARNING - State of this instance has been externally set to None. Terminating instance.
[2025-01-27T19:02:05.068-0300] {process_utils.py:131} INFO - Sending 15 to group 182654. PIDs of all processes in the group: [182654]
[2025-01-27T19:02:05.068-0300] {process_utils.py:86} INFO - Sending the signal 15 to group 182654
[2025-01-27T19:02:05.068-0300] {taskinstance.py:2450} ERROR - Received SIGTERM. Terminating subprocesses.
[2025-01-27T19:02:05.071-0300] {taskinstance.py:2698} ERROR - Task failed with exception
Traceback (most recent call last):
  File "/home/victor/Desktop/TESTE/code-challenge/.meltano/utilities/airflow/venv/lib/python3.11/site-packages/airflow/models/taskinstance.py", line 433, in _execute_task
    result = execute_callable(context=context, **execute_callable_kwargs)
             ^^^^^^^^^^^^^^^^^^^^^^^^^^^^^^^^^^^^^^^^^^^^^^^^^^^^^^^^^^^^
  File "/home/victor/Desktop/TESTE/code-challenge/.meltano/utilities/airflow/venv/lib/python3.11/site-packages/airflow/sensors/external_task.py", line 334, in execute
    super().execute(context)
  File "/home/victor/Desktop/TESTE/code-challenge/.meltano/utilities/airflow/venv/lib/python3.11/site-packages/airflow/sensors/base.py", line 293, in execute
    time.sleep(self._get_next_poke_interval(started_at, run_duration, try_number))
  File "/home/victor/Desktop/TESTE/code-challenge/.meltano/utilities/airflow/venv/lib/python3.11/site-packages/airflow/models/taskinstance.py", line 2452, in signal_handler
    raise AirflowException("Task received SIGTERM signal")
airflow.exceptions.AirflowException: Task received SIGTERM signal
[2025-01-27T19:02:05.073-0300] {taskinstance.py:1138} INFO - Marking task as FAILED. dag_id=load_data, task_id=wait_step_1, execution_date=20250127T215120, start_date=20250127T220052, end_date=20250127T220205
[2025-01-27T19:02:05.077-0300] {standard_task_runner.py:107} ERROR - Failed to execute job 71 for task wait_step_1 ((sqlite3.IntegrityError) FOREIGN KEY constraint failed
[SQL: INSERT INTO task_fail (task_id, dag_id, run_id, map_index, start_date, end_date, duration) VALUES (?, ?, ?, ?, ?, ?, ?)]
[parameters: ('wait_step_1', 'load_data', 'manual__2025-01-27T21:51:20+00:00', -1, '2025-01-27 22:00:52.797500', '2025-01-27 22:02:05.073160', 72)]
(Background on this error at: https://sqlalche.me/e/14/gkpj); 182654)
[2025-01-27T19:02:05.094-0300] {process_utils.py:79} INFO - Process psutil.Process(pid=182654, status='terminated', exitcode=1, started='19:00:52') (182654) terminated with exit code 1
