[2025-01-27T18:51:29.375-0300] {taskinstance.py:1956} INFO - Dependencies all met for dep_context=non-requeueable deps ti=<TaskInstance: load_data.wait_step_1 manual__2025-01-27T21:51:20+00:00 [queued]>
[2025-01-27T18:51:29.379-0300] {taskinstance.py:1956} INFO - Dependencies all met for dep_context=requeueable deps ti=<TaskInstance: load_data.wait_step_1 manual__2025-01-27T21:51:20+00:00 [queued]>
[2025-01-27T18:51:29.379-0300] {taskinstance.py:2170} INFO - Starting attempt 1 of 1
[2025-01-27T18:51:29.514-0300] {taskinstance.py:2191} INFO - Executing <Task(ExternalTaskSensor): wait_step_1> on 2025-01-27 21:51:20+00:00
[2025-01-27T18:51:29.517-0300] {standard_task_runner.py:60} INFO - Started process 179641 to run task
[2025-01-27T18:51:29.520-0300] {standard_task_runner.py:87} INFO - Running: ['airflow', 'tasks', 'run', 'load_data', 'wait_step_1', 'manual__2025-01-27T21:51:20+00:00', '--job-id', '68', '--raw', '--subdir', 'DAGS_FOLDER/step2.py', '--cfg-path', '/tmp/tmpyyfq6eak']
[2025-01-27T18:51:29.521-0300] {standard_task_runner.py:88} INFO - Job 68: Subtask wait_step_1
[2025-01-27T18:51:29.781-0300] {task_command.py:423} INFO - Running <TaskInstance: load_data.wait_step_1 manual__2025-01-27T21:51:20+00:00 [running]> on host victor-MS-7C52
[2025-01-27T18:51:30.012-0300] {taskinstance.py:2480} INFO - Exporting env vars: AIRFLOW_CTX_DAG_OWNER='airflow' AIRFLOW_CTX_DAG_ID='load_data' AIRFLOW_CTX_TASK_ID='wait_step_1' AIRFLOW_CTX_EXECUTION_DATE='2025-01-27T21:51:20+00:00' AIRFLOW_CTX_TRY_NUMBER='1' AIRFLOW_CTX_DAG_RUN_ID='manual__2025-01-27T21:51:20+00:00'
[2025-01-27T18:51:30.013-0300] {external_task.py:244} INFO - Poking for tasks ['organize_folders'] in dag extract_data on 2025-01-27T21:51:20+00:00 ... 
[2025-01-27T18:52:00.095-0300] {external_task.py:244} INFO - Poking for tasks ['organize_folders'] in dag extract_data on 2025-01-27T21:51:20+00:00 ... 
[2025-01-27T18:52:05.334-0300] {local_task_job_runner.py:302} WARNING - State of this instance has been externally set to restarting. Terminating instance.
[2025-01-27T18:52:05.342-0300] {process_utils.py:131} INFO - Sending 15 to group 179641. PIDs of all processes in the group: [179641]
[2025-01-27T18:52:05.342-0300] {process_utils.py:86} INFO - Sending the signal 15 to group 179641
[2025-01-27T18:52:05.342-0300] {taskinstance.py:2450} ERROR - Received SIGTERM. Terminating subprocesses.
[2025-01-27T18:52:05.345-0300] {taskinstance.py:2698} ERROR - Task failed with exception
Traceback (most recent call last):
  File "/home/victor/Desktop/TESTE/code-challenge/.meltano/utilities/airflow/venv/lib/python3.11/site-packages/airflow/models/taskinstance.py", line 433, in _execute_task
    result = execute_callable(context=context, **execute_callable_kwargs)
             ^^^^^^^^^^^^^^^^^^^^^^^^^^^^^^^^^^^^^^^^^^^^^^^^^^^^^^^^^^^^
  File "/home/victor/Desktop/TESTE/code-challenge/.meltano/utilities/airflow/venv/lib/python3.11/site-packages/airflow/sensors/external_task.py", line 334, in execute
    super().execute(context)
  File "/home/victor/Desktop/TESTE/code-challenge/.meltano/utilities/airflow/venv/lib/python3.11/site-packages/airflow/sensors/base.py", line 293, in execute
    time.sleep(self._get_next_poke_interval(started_at, run_duration, try_number))
  File "/home/victor/Desktop/TESTE/code-challenge/.meltano/utilities/airflow/venv/lib/python3.11/site-packages/airflow/models/taskinstance.py", line 2452, in signal_handler
    raise AirflowException("Task received SIGTERM signal")
airflow.exceptions.AirflowException: Task received SIGTERM signal
[2025-01-27T18:52:05.451-0300] {taskinstance.py:1138} INFO - Marking task as UP_FOR_RETRY. dag_id=load_data, task_id=wait_step_1, execution_date=20250127T215120, start_date=20250127T215129, end_date=20250127T215205
[2025-01-27T18:52:05.557-0300] {standard_task_runner.py:107} ERROR - Failed to execute job 68 for task wait_step_1 (Task received SIGTERM signal; 179641)
[2025-01-27T18:52:05.595-0300] {process_utils.py:79} INFO - Process psutil.Process(pid=179641, status='terminated', exitcode=1, started='18:51:28') (179641) terminated with exit code 1
