[2025-01-26T21:40:59.977-0300] {taskinstance.py:1956} INFO - Dependencies all met for dep_context=non-requeueable deps ti=<TaskInstance: my_dag.task1 manual__2025-01-27T00:40:55.853156+00:00 [queued]>
[2025-01-26T21:40:59.981-0300] {taskinstance.py:1956} INFO - Dependencies all met for dep_context=requeueable deps ti=<TaskInstance: my_dag.task1 manual__2025-01-27T00:40:55.853156+00:00 [queued]>
[2025-01-26T21:40:59.981-0300] {taskinstance.py:2170} INFO - Starting attempt 1 of 1
[2025-01-26T21:41:00.096-0300] {taskinstance.py:2191} INFO - Executing <Task(BashOperator): task1> on 2025-01-27 00:40:55.853156+00:00
[2025-01-26T21:41:00.101-0300] {standard_task_runner.py:60} INFO - Started process 79146 to run task
[2025-01-26T21:41:00.104-0300] {standard_task_runner.py:87} INFO - Running: ['airflow', 'tasks', 'run', 'my_dag', 'task1', 'manual__2025-01-27T00:40:55.853156+00:00', '--job-id', '11', '--raw', '--subdir', 'DAGS_FOLDER/testdag.py', '--cfg-path', '/tmp/tmptahw638k']
[2025-01-26T21:41:00.105-0300] {standard_task_runner.py:88} INFO - Job 11: Subtask task1
[2025-01-26T21:41:00.209-0300] {task_command.py:423} INFO - Running <TaskInstance: my_dag.task1 manual__2025-01-27T00:40:55.853156+00:00 [running]> on host victor-MS-7C52
[2025-01-26T21:41:00.394-0300] {taskinstance.py:2480} INFO - Exporting env vars: AIRFLOW_CTX_DAG_OWNER='airflow' AIRFLOW_CTX_DAG_ID='my_dag' AIRFLOW_CTX_TASK_ID='task1' AIRFLOW_CTX_EXECUTION_DATE='2025-01-27T00:40:55.853156+00:00' AIRFLOW_CTX_TRY_NUMBER='1' AIRFLOW_CTX_DAG_RUN_ID='manual__2025-01-27T00:40:55.853156+00:00'
[2025-01-26T21:41:00.395-0300] {subprocess.py:63} INFO - Tmp dir root location: /tmp
[2025-01-26T21:41:00.396-0300] {subprocess.py:75} INFO - Running command: ['/usr/bin/bash', '-c', "'cd /home/victor/Desktop/TESTE/code-challenge; .meltano/run/bin dragon'"]
[2025-01-26T21:41:00.405-0300] {subprocess.py:86} INFO - Output:
[2025-01-26T21:41:00.406-0300] {subprocess.py:93} INFO - /usr/bin/bash: line 1: cd /home/victor/Desktop/TESTE/code-challenge; .meltano/run/bin dragon: No such file or directory
[2025-01-26T21:41:00.406-0300] {subprocess.py:97} INFO - Command exited with return code 127
[2025-01-26T21:41:00.490-0300] {taskinstance.py:2698} ERROR - Task failed with exception
Traceback (most recent call last):
  File "/home/victor/Desktop/TESTE/code-challenge/.meltano/utilities/airflow/venv/lib/python3.11/site-packages/airflow/models/taskinstance.py", line 433, in _execute_task
    result = execute_callable(context=context, **execute_callable_kwargs)
             ^^^^^^^^^^^^^^^^^^^^^^^^^^^^^^^^^^^^^^^^^^^^^^^^^^^^^^^^^^^^
  File "/home/victor/Desktop/TESTE/code-challenge/.meltano/utilities/airflow/venv/lib/python3.11/site-packages/airflow/operators/bash.py", line 212, in execute
    raise AirflowException(
airflow.exceptions.AirflowException: Bash command failed. The command returned a non-zero exit code 127.
[2025-01-26T21:41:00.493-0300] {taskinstance.py:1138} INFO - Marking task as FAILED. dag_id=my_dag, task_id=task1, execution_date=20250127T004055, start_date=20250127T004059, end_date=20250127T004100
[2025-01-26T21:41:00.613-0300] {standard_task_runner.py:107} ERROR - Failed to execute job 11 for task task1 (Bash command failed. The command returned a non-zero exit code 127.; 79146)
[2025-01-26T21:41:00.637-0300] {local_task_job_runner.py:234} INFO - Task exited with return code 1
[2025-01-26T21:41:00.645-0300] {taskinstance.py:3280} INFO - 0 downstream tasks scheduled from follow-on schedule check
